Workbook
Name BFSI_Projects: Projects!$G$3:$G$21
Name CES_Projects: Projects!$D$3:$D$21
Name EPCS_Projects: Projects!$P$3:$P$21
Name EPS_Projects: Projects!$J$3:$J$21
Name ERP_Projects: Projects!$A$3:$A$21
Name GRC_Projects: Projects!$M$3:$M$21

Sheet LOVs
A1: Task Category | B1: AI Tool Used
A2: Development | B2: Github Copilot
A3: Database | B3: Cursor
A4: Documentation | B4: Codex
A5: Testing | B5: Claude
A6: Code Review | B6: ChatGPT
B7: Gemini

Sheet Summary
A1: EAS AI Adoption – Overall Weekly Progress Summary
A2: EAS Overall AI SPOC: Omar Ibrahim
A4: Practice-Level Weekly Summary
A5: Practice | B5: Practice Head | C5: AI SPOC | D5: Total Tasks | E5: Time Without AI (hrs) | F5: Time With AI (hrs) | G5: Time Saved (hrs) | H5: Avg Efficiency % | I5: Avg Quality (1-5) | J5: Completed Tasks | K5: Projects
A6: ERP Solutions | B6: Amer Farghaly | C6: Reham Ibrahim | D6: =COUNTA(ERP!G7:G46) -> 5 | E6: =SUM(ERP!K7:K46) -> 156 | F6: =SUM(ERP!L7:L46) -> 72 | G6: =SUM(ERP!M7:M46) -> 84 | H6: =IFERROR(AVERAGE(ERP!N7:N46),"") -> 0.53333333 | I6: =IFERROR(AVERAGE(ERP!O7:O46),"") | J6: =COUNTIF(ERP!P7:P46,"Completed") -> 5 | K6: =COUNTA(ERP_Projects) -> 2
A7: Customer Engagement Solutions | B7: Osama Nagdy | C7: Norah Al Wabel | D7: =COUNTA(CES!G7:G46) -> 7 | E7: =SUM(CES!K7:K46) -> 286 | F7: =SUM(CES!L7:L46) -> 174.5 | G7: =SUM(CES!M7:M46) -> 111.5 | H7: =IFERROR(AVERAGE(CES!N7:N46),"") -> 0.60037879 | I7: =IFERROR(AVERAGE(CES!O7:O46),"") -> 3.6666667 | J7: =COUNTIF(CES!P7:P46,"Completed") -> 6 | K7: =COUNTA(CES_Projects) -> 3
A8: Financial Services Solutions (BFSI) | B8: Mohab ElHaddad | C8: Omar Ibrahim | D8: =COUNTA(BFSI!G7:G45) -> 29 | E8: =SUM(BFSI!K7:K45) -> 160 | F8: =SUM(BFSI!L7:L45) -> 72.35 | G8: =SUM(BFSI!M7:M45) -> 87.65 | H8: =IFERROR(AVERAGE(BFSI!N7:N45),"") -> 0.5089491 | I8: =IFERROR(AVERAGE(BFSI!O7:O45),"") -> 4.2 | J8: =COUNTIF(BFSI!P7:P45,"Completed") -> 29 | K8: =COUNTA(BFSI_Projects) -> 11
A9: Payments Solutions EPS | B9: Mohamed Ziaudin | C9: Yousef Milhem | D9: =COUNTA(EPS!G7:G46) -> 6 | E9: =SUM(EPS!K7:K46) -> 2.5 | F9: =SUM(EPS!L7:L46) -> 0.01 | G9: =SUM(EPS!M7:M46) -> 0.49 | H9: =IFERROR(AVERAGE(EPS!N7:N46),"") -> 0.98 | I9: =IFERROR(AVERAGE(EPS!O7:O46),"") -> 4 | J9: =COUNTIF(EPS!P7:P46,"Completed") -> 1 | K9: =COUNTA(EPS_Projects) -> 2
A10: GRC | B10: Ahmed Madkour | C10: Mohamed Essam | D10: =COUNTA(GRC!G7:G44) -> 6 | E10: =SUM(GRC!K7:K44) -> 30 | F10: =SUM(GRC!L7:L44) -> 5.25 | G10: =SUM(GRC!M7:M44) -> 24.75 | H10: =IFERROR(AVERAGE(GRC!N7:N44),"") -> 0.84722222 | I10: =IFERROR(AVERAGE(GRC!O7:O44),"") -> 4.6666667 | J10: =COUNTIF(GRC!P7:P44,"Completed") -> 6 | K10: =COUNTA(GRC_Projects) -> 3
A11: Enterprise Portfolio & Content Solutions | B11: Mohamed Mobarak | C11: Ahmed Shaheen | D11: =COUNTA(EPCS!G7:G46) -> 3 | E11: =SUM(EPCS!K7:K46) -> 0 | F11: =SUM(EPCS!L7:L46) -> 0 | G11: =SUM(EPCS!M7:M46) -> 0 | H11: =IFERROR(AVERAGE(EPCS!N7:N46),"") | I11: =IFERROR(AVERAGE(EPCS!O7:O46),"") -> 4.6666667 | J11: =COUNTIF(EPCS!P7:P46,"Completed") -> 0 | K11: =COUNTA(EPCS_Projects) -> 4
A12: OVERALL TOTAL | D12: =SUM(D6:D11) -> 56 | E12: =SUM(E6:E11) -> 634.5 | F12: =SUM(F6:F11) -> 324.11 | G12: =SUM(G6:G11) -> 308.39 | H12: =IFERROR(AVERAGE(H6:H11),"") -> 0.69397669 | I12: =IFERROR(AVERAGE(I6:I11),"") -> 4.24 | J12: =SUM(J6:J11) -> 47 | K12: =SUM(K6:K11) -> 25
A15: Time Saved by Practice (hrs)

Sheet AI Accomplishments
A1: EAS AI Adoption – Standalone Accomplishments Log
A2: Record notable AI-driven wins, POCs, and value-adds that fall outside regular weekly task tracking.
A4: # | B4: Date | C4: Practice | D4: Project | E4: Project Code | F4: SPOC / Lead | G4: Employee(s) Involved | H4: Accomplishment Title | I4: Accomplishment Details | J4: AI Tool Used | K4: Category | L4: Before AI (Baseline) | M4: After AI (Result) | N4: Quantified Impact | O4: Business Gains | P4: Cost to Client | Q4: Effort Saved (hrs) | R4: Status | S4: Evidence / Links | T4: Management Notes
A5: =IF(H5<>"",ROW()-4,"") -> 1 | B5: 46081 | C5: BFSI | D5: Go Money | F5: Omar Ibrahim | G5: Moemen Morsy/Al Moataz ibrahim | H5: Full LMS Code Review & Remediation | I5: Performed a comprehensive code review of the entire LMS codebase using GitHub Copilot. Identified critical code quality issues, security vulnerabilities, and performance bottlenecks. Applied AI-assisted code modifications and refactoring to improve maintainability, readability, and overall health of the codebase. | J5: Github Copilot | K5: Code Review | L5: Health Score: 2.5 / 10 | M5: Health Score: 6.8 / 10 | N5: Health score improved by +4.3 (172% improvement) | O5: Client trust & confidence restored; reduced technical debt; improved code maintainability; strengthened delivery credibility | P5: Free of Cost | R5: Completed | T5: First AI accomplishment logged for BFSI practice
A6: 2 | B6: 46078 | C6: EPCS | D6: IT & Digital Transformation - Clarity Implementation | E6: C1009701 | F6: Ahmed Shaheen | G6: Eyad Ahmed / Menna Allah Ali | H6: AI‑assisted data migration validation & export | I6: Built a Python Tkinter desktop application that automates end‑to‑end data migration prep. The app ingests .xlsx files, applies JSON‑based validation rules, highlights invalid rows with error reasons, enables in‑app corrections, and exports both an error report (.xlsx) and multiple import‑ready .csv batches (<=200 rows). Validation rules are configurable and reusable, reducing manual review, rework, and import delays. | J6: Github Copilot | K6: Application Development | L6: Cycle Time: 3.0 hrs per file | M6: Cycle Time: 1.0 hr per file | N6: Time reduced from 3 hrs to 1 hr per file (‑2 hrs, ~67% faster). | O6: Faster turnaround, fewer errors, standardized validation and batching. | P6: Free of Cost | Q6: 2 | R6: Completed | S6: Demo
A7: =IF(H7<>"",ROW()-4,"") -> 3 | B7: 46145 | C7: EPCS | D7: ART - Alfresco DMS Production Support Services | E7: 14005204 | F7: Ahmed AlSareti | G7: Omar GamalEldeen / Abdullah Al Duwaihi / Mahinour Emad Kadry | H7: application development and configuration | I7: add and configure HTTP-to-HTTPS proxy to Alfresco Kubernetes cluster to keep Elastisearch secured | J7: Github Copilot | K7: Application configuration | N7: Development and configuration time had been reduced from 8 hrs to 1 hr | O7: Faser to finalize customer CR | P7: Free of Cost | Q7: 8 | R7: testing
A8: =IF(H8<>"",ROW()-4,"") -> 4 | B8: 15/3/2026 | C8: EPCS | D8: DMS Activities | E8: 51014108-001 | F8: Ahmed AlSareti | G8: Omar GamalEldeen / Abdullah Al Duwaihi / Mahinour Emad Kadry | H8: application development | I8: update Alfresco workspace front-end application (Angular) to allow search by metadata | J8: Github Copilot | K8: Application Development | N8: Development and configuration time had been reduced from 1 week to 2 days | O8: enhance internal web applications development | P8: Free of Cost | R8: Completed | S8: https://github.com/ejadasa-copilot-business/alfresco-digital-workspace
A9: =IF(H9<>"",ROW()-4,"")
A10: =IF(H10<>"",ROW()-4,"")
A11: =IF(H11<>"",ROW()-4,"")
A12: =IF(H12<>"",ROW()-4,"")
A13: =IF(H13<>"",ROW()-4,"")
A14: =IF(H14<>"",ROW()-4,"")
A15: =IF(H15<>"",ROW()-4,"")
A16: =IF(H16<>"",ROW()-4,"")
A17: =IF(H17<>"",ROW()-4,"")
A18: =IF(H18<>"",ROW()-4,"")
A19: =IF(H19<>"",ROW()-4,"")
A20: =IF(H20<>"",ROW()-4,"")
... A34: =IF(H34<>"",ROW()-4,"")

Sheet Projects
A1: ERP Projects | D1: CES Projects | G1: BFSI Projects | J1: EPS Projects | M1: GRC Projects | P1: EPCS Projects
A2: Project Name | B2: Project Code | D2: Project Name | E2: Project Code | G2: Project Name | H2: Project Code | J2: Project Name | K2: Project Code | M2: Project Name | N2: Project Code | P2: Project Name | Q2: Project Code
A3: RRM ERP Cloud Services Implementation | B3: 56000301 | D3: MOH - Portals Support & Management | E3: 62002301 | G3: Project C-Personal Finance | H3: 12135001 | J3: Migration of TiPlus backend interfaces to MQ based MT & MX | K3: 12158001 | M3: VAT Application Support | N3: 12164301 | P3: ART - Alfresco DMS Production Support Services | Q3: 14005204
A4: ITSM Project | B4: C1007201 | D4: تطوير الملف التعريفي الموحد للعملاء | E4: 53008701 | G4: Go Money MICRO FINANCE LENDING PLATFORM | H4: A1023401 | J4: ANB EPS Corporate Module | K4: 12150101 | M4: ANB Change Request VAT Reconcilation | N4: 12144401 | P4: DMS Activities | Q4: 51014108-001
D5: tawtheeq service now crm | E5: 23045701 | G5: Emkan E-Commerce | H5: 13011901 | M5: ANB Consumer Loans Historical Reconcilation | N5: 12154701 | P5: IT & Digital Transformation - Clarity Implementation | Q5: C1009701
G6: Emkan Revamp | H6: 13012501 | P6: RRM ERP Cloud Services Implementation 15/12/2025 | Q6: 56000301
G7: Emkan - BNPL Implementation (LMS + LOS) | H7: 13005301
G8: Emkan - Apple Project Implementation | H8: 13008001
G9: Emkan - SME Product Suite Implementation (B2B) | H9: 13008101
G10: EMKAN Vulnerability Report | H10: 13013201
G11: TDF Transact Support and Enhancement - Temenos T24 | H11: 94000802
G12: TDF - Risk Monitoring and Reporting Portal | H12: 94000601
G13: ARB Digital Core Banking - Personal Finance | H13: 12170301

Sheet Copliot User Access
A1: Pracitce | B1: Resource Name | C1: Resource Emaid ID | D1: Skill | E1: Remarks | F1: Business line
A2: BFSI | B2: Ibrahim Amin | C2: iamin@ejada.com | D2: Developer Team Lead | E2: access granted | F2: LOS
A3: BFSI | B3: Omar Ghazalah | C3: oghazalah@ejada.com | D3: Developer Team Lead | E3: access granted | F3: LOS
A4: BFSI | B4: Omar Ibrahim | C4: oibrahim@ejada.com | D4: Solution Architect | E4: access granted
A5: BFSI | B5: Amr Akady | C5: amr.alkady@ejada.com | D5: Solution Architect | E5: access granted
A6: BFSI | B6: Miral Soliman | C6: miral.soliman@ejada.com | D6: Business Analyst | E6: access granted
A7: BFSI | B7: Gahada Bakry | C7: gbakry@ejada.com | D7: Business Analyst | E7: access granted
A8: BFSI | B8: Bassem Nasr | C8: basim.nasir@ejada.com | D8: LEAD BUSINESS ARCHITECT | E8: access granted
A9: BFSI | B9: Mohammed Omar Eid | C9: moeid@ejada.com | D9: Senior Enterprise Architect | E9: access granted
A10: BFSI | B10: Islam Mohamed | C10: imohamed@ejada.com | D10: Analyst/Senior Developer | E10: access granted | F10: LOS
A11: BFSI | B11: Nourane Elkhawalka | C11: nelkhawalka@ejada.com | D11: Delivery Manager | E11: access granted
A12: BFSI | B12: Sabreen AbdElmaguid | C12: sabdelmaguid@ejada.com | D12: Developer Team Lead | E12: access granted | F12: LOS
A13: BFSI | B13: Youssuf Elshayeb | C13: yelshayeb@ejada.com | D13: Developer | E13: access granted | F13: LOS
A14: BFSI | B14: Farah Hassaan | C14: fhassaan@ejada.com | D14: Developer | E14: access granted | F14: LOS
A15: BFSI | B15: Moustafa Daebis | C15: mdaebis@ejada.com | D15: Developer | E15: access granted | F15: LOS
A16: BFSI | B16: Seif Eldin Amr | C16: seifeldin.amr@ejada.com | D16: Developer | E16: access granted | F16: LOS
A17: BFSI | B17: AL-Moataz Bellah Khamis Ahmed | C17: abellah@ejada.com | D17: Developer | E17: access granted | F17: LOS
A18: BFSI | B18: Nour Eldin Hazem Abdelsalam | C18: nhabdelsalam@ejada.com | D18: Developer | E18: access granted
A19: BFSI | B19: Yara Elmelegy | C19: yelmelegy@ejada.com | D19: Developer | E19: access granted
A20: BFSI | B20: Rafeef Alsealo | C20: ralsealo@ejada.com | D20: Business Analyst | E20: access granted
A21: BFSI | B21: Abdulrahman Alafandy | C21: aalafandy@ejada.com | D21: Technical Team Lead | E21: access granted | F21: LOS
A22: BFSI | B22: Ahmed Said Mohamed | C22: amsaid@ejada.com | D22: Developer | E22: access granted | F22: LOS
A23: BFSI | B23: Mariam Elshimi | C23: melshimi@ejada.com | D23: Developer | E23: access granted | F23: LOS
A24: BFSI | B24: Manar Elsayed | C24: maelsayed-v@ejada.com | D24: Developer | E24: pending | F24: LOS
A25: BFSI | B25: Maram Motaz | C25: mmotaz@ejada.com | D25: Developer | E25: access granted | F25: LOS
A26: BFSI | B26: Ahmad Nouh | C26: anouh@ejada.com | D26: Developer | E26: access granted
A27: BFSI | B27: Farah Elgendy | C27: felgendy@ejada.com | D27: Developer | E27: access granted
A28: BFSI | B28: Salma Ahmed Abdelsalam Mostafa | C28: salma.ahmed@ejada.com | D28: Developer | E28: access granted
A29: BFSI | B29: Ziad Elkhazendar | C29: zelkhazendar@ejada.com | D29: Developer | E29: access granted
A30: BFSI | B30: Ingy Ibrahim | C30: iibrahim@ejada.com | D30: Developer | E30: access granted
A31: BFSI | B31: Hossam Gamal Abdelhaleem | C31: hgamal@ejada.com | D31: Technical Project Manager | E31: access granted | F31: LOS
A32: BFSI | B32: Amr Nady | C32: anady@ejada.com | D32: Developer | E32: access granted | F32: LOS
A33: BFSI | B33: Ahmed Elsahamy | C33: aelsahlamy@ejada.com | D33: Developer | E33: access granted | F33: LOS
A34: BFSI | B34: Ahmad Elkilany | C34: aelkilany@ejada.com | D34: Developer | E34: access granted | F34: LOS
A35: BFSI | B35: AbdelRahman Badr Kamel | C35: abadr@ejada.com | D35: Technical Team Lead | E35: access granted | F35: LOS
A36: BFSI | B36: Marry Waseem | C36: mwaseem@ejada.com | D36: Developer | E36: access granted | F36: LOS
A37: BFSI | B37: Abdelrahman Mohamed Khalil | C37: amkhalil@ejada.com | D37: Developer | E37: access granted | F37: LOS
A38: BFSI | B38: Mohammed Abdulelah Al Harbi | C38: maalharbi@ejada.com | D38: Developer | E38: access granted | F38: LOS
A39: BFSI | B39: Yahia Zaky | C39: yzaky@ejada.com | D39: Developer | E39: access granted | F39: LOS
A40: BFSI | B40: Youmna Elmezyn | C40: yelmezyn@ejada.com | D40: Developer | E40: access granted | F40: LOS
...

Sheet CES
A1: EAS AI Adoption – Weekly Tracking Sheet – Customer Engagement Solutions
A2: EAS Overall AI SPOC: | D2: Omar Ibrahim
A3: CES Practice Head: | D3: Osama Nagdy
A4: CES AI SPOC: | D4: Norah Al Wabel & Ramy Moustafa Elshishtawy Elmor | G4: CRM
A6: Week # | B6: Week Start Date | C6: Week End Date | D6: Project Name | E6: Project Code | F6: Employee Name | G6: Task / Activity | H6: Task Category | I6: AI Tool Used | J6: Prompt / Approach | K6: Time Without AI (hrs) | L6: Time With AI (hrs) | M6: Time Saved (hrs) | N6: Efficiency Gain % | O6: Quality Rating (1-5) | P6: Status | Q6: Notes / Learnings
D7: infath care | E7: =IFERROR(VLOOKUP(D7,Projects!$D$3:$E$21,2,FALSE),"") | F7: Ramy Mustafa | G7: generate HLD including diagrams | H7: Documentation | I7: ChatGPT and eraser ai | K7: 132 | L7: 84 | M7: =IF(AND(K7<>"",L7<>""),K7-L7,"") -> 48 | N7: =IF(AND(M7<>"",K7<>"",K7<>0),M7/K7,"") -> 0.36363636 | O7: 3 | P7: Completed
D8: bog | E8: =IFERROR(VLOOKUP(D8,Projects!$D$3:$E$21,2,FALSE),"") | F8: Ramy Mustafa | G8: generate HLD including diagrams | H8: Documentation | I8: ChatGPT and eraser ai | K8: 132 | L8: 84 | M8: =IF(AND(K8<>"",L8<>""),K8-L8,"") -> 48 | N8: =IF(AND(M8<>"",K8<>"",K8<>0),M8/K8,"") -> 0.36363636 | O8: 2 | P8: Completed
D9: bog | E9: =IFERROR(VLOOKUP(D9,Projects!$D$3:$E$21,2,FALSE),"") | F9: Ramy Mustafa | G9: development | H9: Development | I9: ChatGPT and eraser ai | M9: =IF(AND(K9<>"",L9<>""),K9-L9,"") | N9: =IF(AND(M9<>"",K9<>"",K9<>0),M9/K9,"") | P9: In Progress
A10: 2 | B10: 22/2/2026 | C10: 26/2/2026 | D10: تطوير الملف التعريفي الموحد للعملاء | E10: =IFERROR(VLOOKUP(D10,Projects!$D$3:$E$21,2,FALSE),"") -> 53008701 | F10: Ahmed Ibrahim | G10: UI design for CRM form | H10: Development | I10: ChatGPT | J10: Ask chatGPT to suggest for design based on customer requirements | K10: 8 | L10: 3 | M10: =IF(AND(K10<>"",L10<>""),K10-L10,"") -> 5 | N10: =IF(AND(M10<>"",K10<>"",K10<>0),M10/K10,"") -> 0.625 | O10: 4 | P10: Completed
A11: 2 | B11: 22/2/2026 | C11: 26/2/2026 | D11: تطوير الملف التعريفي الموحد للعملاء | E11: =IFERROR(VLOOKUP(D11,Projects!$D$3:$E$21,2,FALSE),"") -> 53008701 | F11: Malak Madkour | G11: code review | H11: Code Review | I11: Github Copilot | J11: Ask copilot to fix bugs | K11: 2 | L11: 0.5 | M11: =IF(AND(K11<>"",L11<>""),K11-L11,"") -> 1.5 | N11: =IF(AND(M11<>"",K11<>"",K11<>0),M11/K11,"") -> 0.75 | O11: 5 | P11: Completed
A12: 2 | B12: 22/2/2026 | C12: 26/2/2026 | D12: تطوير الملف التعريفي الموحد للعملاء | E12: =IFERROR(VLOOKUP(D12,Projects!$D$3:$E$21,2,FALSE),"") -> 53008701 | F12: Malak Madkour | G12: auctions module development | H12: Development | I12: Github Copilot | J12: Ask copilot to assist in model creation and mapping to CRM | K12: 4 | L12: 1 | M12: =IF(AND(K12<>"",L12<>""),K12-L12,"") -> 3 | N12: =IF(AND(M12<>"",K12<>"",K12<>0),M12/K12,"") -> 0.75 | O12: 4 | P12: Completed
A13: 2 | B13: 22/2/2026 | C13: 26/2/2026 | D13: تطوير الملف التعريفي الموحد للعملاء | E13: =IFERROR(VLOOKUP(D13,Projects!$D$3:$E$21,2,FALSE),"") -> 53008701 | F13: Fady Banoub | G13: HTML and CSS web resources for UI design | H13: Development | I13: Github Copilot | J13: Ask copilot to assist in building CSS and HTML files | K13: 8 | L13: 2 | M13: =IF(AND(K13<>"",L13<>""),K13-L13,"") -> 6 | N13: =IF(AND(M13<>"",K13<>"",K13<>0),M13/K13,"") -> 0.75 | O13: 4 | P13: Completed
E14: =IFERROR(VLOOKUP(D14,Projects!$D$3:$E$21,2,FALSE),"") | M14: =IF(AND(K14<>"",L14<>""),K14-L14,"") | N14: =IF(AND(M14<>"",K14<>"",K14<>0),M14/K14,"")
E15: =IFERROR(VLOOKUP(D15,Projects!$D$3:$E$21,2,FALSE),"") | M15: =IF(AND(K15<>"",L15<>""),K15-L15,"") | N15: =IF(AND(M15<>"",K15<>"",K15<>0),M15/K15,"")
E16: =IFERROR(VLOOKUP(D16,Projects!$D$3:$E$21,2,FALSE),"") | M16: =IF(AND(K16<>"",L16<>""),K16-L16,"") | N16: =IF(AND(M16<>"",K16<>"",K16<>0),M16/K16,"")
E17: =IFERROR(VLOOKUP(D17,Projects!$D$3:$E$21,2,FALSE),"") | M17: =IF(AND(K17<>"",L17<>""),K17-L17,"") | N17: =IF(AND(M17<>"",K17<>"",K17<>0),M17/K17,"")
E18: =IFERROR(VLOOKUP(D18,Projects!$D$3:$E$21,2,FALSE),"") | M18: =IF(AND(K18<>"",L18<>""),K18-L18,"") | N18: =IF(AND(M18<>"",K18<>"",K18<>0),M18/K18,"")
E19: =IFERROR(VLOOKUP(D19,Projects!$D$3:$E$21,2,FALSE),"") | M19: =IF(AND(K19<>"",L19<>""),K19-L19,"") | N19: =IF(AND(M19<>"",K19<>"",K19<>0),M19/K19,"")
E20: =IFERROR(VLOOKUP(D20,Projects!$D$3:$E$21,2,FALSE),"") | M20: =IF(AND(K20<>"",L20<>""),K20-L20,"") | N20: =IF(AND(M20<>"",K20<>"",K20<>0),M20/K20,"")
E21: =IFERROR(VLOOKUP(D21,Projects!$D$3:$E$21,2,FALSE),"") | M21: =IF(AND(K21<>"",L21<>""),K21-L21,"") | N21: =IF(AND(M21<>"",K21<>"",K21<>0),M21/K21,"")
E22: =IFERROR(VLOOKUP(D22,Projects!$D$3:$E$21,2,FALSE),"") | M22: =IF(AND(K22<>"",L22<>""),K22-L22,"") | N22: =IF(AND(M22<>"",K22<>"",K22<>0),M22/K22,"")
E23: =IFERROR(VLOOKUP(D23,Projects!$D$3:$E$21,2,FALSE),"") | M23: =IF(AND(K23<>"",L23<>""),K23-L23,"") | N23: =IF(AND(M23<>"",K23<>"",K23<>0),M23/K23,"")
E24: =IFERROR(VLOOKUP(D24,Projects!$D$3:$E$21,2,FALSE),"") | M24: =IF(AND(K24<>"",L24<>""),K24-L24,"") | N24: =IF(AND(M24<>"",K24<>"",K24<>0),M24/K24,"")
E25: =IFERROR(VLOOKUP(D25,Projects!$D$3:$E$21,2,FALSE),"") | M25: =IF(AND(K25<>"",L25<>""),K25-L25,"") | N25: =IF(AND(M25<>"",K25<>"",K25<>0),M25/K25,"")
... E46: =IFERROR(VLOOKUP(D46,Projects!$D$3:$E$21,2,FALSE),"") | M46: =IF(AND(K46<>"",L46<>""),K46-L46,"") | N46: =IF(AND(M46<>"",K46<>"",K46<>0),M46/K46,"")
A49: CES – Weekly Aggregated Summary
A50: Metric | B50: Value
A51: Total Tasks Logged | B51: =COUNTA(G7:G46) -> 7
A52: Total Time Without AI (hrs) | B52: =SUM(K7:K46) -> 286
A53: Total Time With AI (hrs) | B53: =SUM(L7:L46) -> 174.5
A54: Total Time Saved (hrs) | B54: =SUM(M7:M46) -> 111.5
A55: Average Efficiency Gain % | B55: =IFERROR(AVERAGE(N7:N46),"") -> 0.60037879
A56: Average Quality Rating | B56: =IFERROR(AVERAGE(O7:O46),"") -> 3.6666667
A57: Tasks Completed | B57: =COUNTIF(P7:P46,"Completed") -> 6
A58: Tasks In Progress | B58: =COUNTIF(P7:P46,"In Progress") -> 1

Sheet ERP
A1: EAS AI Adoption – Weekly Tracking Sheet – ERP Solutions
A2: EAS Overall AI SPOC: | D2: Omar Ibrahim
A3: ERP Practice Head: | D3: Amer Farghaly
A4: ERP AI SPOC: | D4: Reham Ibrahim
A6: Week # | B6: Week Start Date | C6: Week End Date | D6: Project Name | E6: Project Code | F6: Employee Name | G6: Task / Activity | H6: Task Category | I6: AI Tool Used | J6: Prompt / Approach | K6: Time Without AI (hrs) | L6: Time With AI (hrs) | M6: Time Saved (hrs) | N6: Efficiency Gain % | O6: Quality Rating (1-5) | P6: Status | Q6: Notes / Learnings
A7: 12 | B7: 30/3/2026 | C7: 46114 | D7: RRM ERP Cloud Services Implementation 15/12/2025 | E7: 56000301 | F7: Nour Nafady | G7: Created an Oracle Fusion Cloud Applications ESS Job to trigger an integration and documented the end-to-end implementation steps. | H7: (Integration)Fusion Development & Documentation | J7: Claude | P7: Completed
A8: 12 | B8: 30/3/2026 | C8: 46114 | D8: RRM ERP Cloud Services Implementation 15/12/2025 | E8: 56000301 | F8: Khaled Ossama | G8: REST API testing and validation for Oracle Fusion Cloud Procurement supplier management endpoints. | H8: Integration - Fusion API Exploration & Validation | J8: Claude | P8: Completed
A9: 12 | B9: 30/3/2026 | C9: 46114 | D9: RRM ERP Cloud Services Implementation 15/12/2025 | E9: 56000301 | F9: Sama Abdullah Zakaria Abu El Naga | G9: Advanced DOR Customization – Dynamic Redwood UI Behavior (Auto-sync fields based on DOR ID) | H9: Visual Builder Oracle Fusion – Advanced Customization | I9: Implemented complex dynamic behavior where selecting a DOR ID triggers full UI field refresh and population using JavaScript, REST integration, variables, and reactive bindings; leveraged AI to overcome Redwood limitations, troubleshoot tricky logic, and accelerate solution design | J9: Claude | K9: 48 | L9: 24 | M9: =IF(AND(K9<>"",L9<>""),K9-L9,"") -> 24 | N9: =IF(AND(M9<>"",K9<>"",K9<>0),M9/K9,"") -> 0.5 | P9: Completed
A10: 12 | B10: 46110 | C10: 46057 | D10: RRM ERP Cloud Services Implementation 15/12/2025 | E10: 56000301 | F10: Mohamed Emad Ahmed | G10: Use a Field Change (fetchComponent / valueChangeHandler) on fields. Whenever either field changes, trigger a function that reads both values, runs the calculation, and writes the result back into | H10: Visual Builder Oracle Fusion – Advanced Customization | I10: You are a senior Oracle Visual Builder (VB) and JavaScript developer. I have a DFF (Descriptive Flexfield) form in Oracle HCM Cloud. Context: Task: Write a valueChangeHandler function in the Oracle VB module pattern define([], () => { ... }) that: Triggers when any of the input fields change Reads the current value of all input fields from the parent path above Applies the calculation rule to produce the output value Writes the result back into the output field using its .$value(newValue) setter Guards against missing, null, or invalid inputs — writes '' to the output field in those cases Logs clearly to the console at each step using the tag [CONTEXT_NAME] for easy filtering Follows the Oracle VB module pattern with JSDoc comment, clean indentation, and early-return guards | J10: Claude | K10: 60 | L10: 24 | M10: =IF(AND(K10<>"",L10<>""),K10-L10,"") -> 36 | N10: =IF(AND(M10<>"",K10<>"",K10<>0),M10/K10,"") -> 0.6 | P10: Completed
A11: 13 | B11: 46117 | C11: 46121 | D11: Oracle - RRM ERP Cloud Services Implementation 15/12/2025 | E11: 56000301 | F11: Haneen Alshamrani | G11: Created a report that accepts a year parameter and retrieves Purchase Orders (POs) within the specified year, supporting both Gregorian and Hijri calendars. The report returns all required fields as defined in the Feedback table according to the Functional Design Document. | H11: interation - report | J11: copilot - GPT - gemini | K11: 48 | L11: 24 | M11: =IF(AND(K11<>"",L11<>""),K11-L11,"") -> 24 | N11: =IF(AND(M11<>"",K11<>"",K11<>0),M11/K11,"") -> 0.5 | P11: Completed
E12: =IFERROR(VLOOKUP(D12,Projects!$A$3:$B$21,2,FALSE),"") | M12: =IF(AND(K12<>"",L12<>""),K12-L12,"") | N12: =IF(AND(M12<>"",K12<>"",K12<>0),M12/K12,"")
E13: =IFERROR(VLOOKUP(D13,Projects!$A$3:$B$21,2,FALSE),"") | M13: =IF(AND(K13<>"",L13<>""),K13-L13,"") | N13: =IF(AND(M13<>"",K13<>"",K13<>0),M13/K13,"")
M14: =IF(AND(K14<>"",L14<>""),K14-L14,"") | N14: =IF(AND(M14<>"",K14<>"",K14<>0),M14/K14,"")
E15: =IFERROR(VLOOKUP(D15,Projects!$A$3:$B$21,2,FALSE),"") | M15: =IF(AND(K15<>"",L15<>""),K15-L15,"") | N15: =IF(AND(M15<>"",K15<>"",K15<>0),M15/K15,"")
E16: =IFERROR(VLOOKUP(D16,Projects!$A$3:$B$21,2,FALSE),"") | M16: =IF(AND(K16<>"",L16<>""),K16-L16,"") | N16: =IF(AND(M16<>"",K16<>"",K16<>0),M16/K16,"")
E17: =IFERROR(VLOOKUP(D17,Projects!$A$3:$B$21,2,FALSE),"") | M17: =IF(AND(K17<>"",L17<>""),K17-L17,"") | N17: =IF(AND(M17<>"",K17<>"",K17<>0),M17/K17,"")
E18: =IFERROR(VLOOKUP(D18,Projects!$A$3:$B$21,2,FALSE),"") | M18: =IF(AND(K18<>"",L18<>""),K18-L18,"") | N18: =IF(AND(M18<>"",K18<>"",K18<>0),M18/K18,"")
E19: =IFERROR(VLOOKUP(D19,Projects!$A$3:$B$21,2,FALSE),"") | M19: =IF(AND(K19<>"",L19<>""),K19-L19,"") | N19: =IF(AND(M19<>"",K19<>"",K19<>0),M19/K19,"")
E20: =IFERROR(VLOOKUP(D20,Projects!$A$3:$B$21,2,FALSE),"") | M20: =IF(AND(K20<>"",L20<>""),K20-L20,"") | N20: =IF(AND(M20<>"",K20<>"",K20<>0),M20/K20,"")
E21: =IFERROR(VLOOKUP(D21,Projects!$A$3:$B$21,2,FALSE),"") | M21: =IF(AND(K21<>"",L21<>""),K21-L21,"") | N21: =IF(AND(M21<>"",K21<>"",K21<>0),M21/K21,"")
E22: =IFERROR(VLOOKUP(D22,Projects!$A$3:$B$21,2,FALSE),"") | M22: =IF(AND(K22<>"",L22<>""),K22-L22,"") | N22: =IF(AND(M22<>"",K22<>"",K22<>0),M22/K22,"")
E23: =IFERROR(VLOOKUP(D23,Projects!$A$3:$B$21,2,FALSE),"") | M23: =IF(AND(K23<>"",L23<>""),K23-L23,"") | N23: =IF(AND(M23<>"",K23<>"",K23<>0),M23/K23,"")
D24: ITSM Project | E24: C1007201 | M24: =IF(AND(K24<>"",L24<>""),K24-L24,"") | N24: =IF(AND(M24<>"",K24<>"",K24<>0),M24/K24,"")
E25: =IFERROR(VLOOKUP(D25,Projects!$A$3:$B$21,2,FALSE),"") | M25: =IF(AND(K25<>"",L25<>""),K25-L25,"") | N25: =IF(AND(M25<>"",K25<>"",K25<>0),M25/K25,"")
E26: =IFERROR(VLOOKUP(D26,Projects!$A$3:$B$21,2,FALSE),"") | M26: =IF(AND(K26<>"",L26<>""),K26-L26,"") | N26: =IF(AND(M26<>"",K26<>"",K26<>0),M26/K26,"")
E27: =IFERROR(VLOOKUP(D27,Projects!$A$3:$B$21,2,FALSE),"") | M27: =IF(AND(K27<>"",L27<>""),K27-L27,"") | N27: =IF(AND(M27<>"",K27<>"",K27<>0),M27/K27,"")
E28: =IFERROR(VLOOKUP(D28,Projects!$A$3:$B$21,2,FALSE),"") | M28: =IF(AND(K28<>"",L28<>""),K28-L28,"") | N28: =IF(AND(M28<>"",K28<>"",K28<>0),M28/K28,"")
E29: =IFERROR(VLOOKUP(D29,Projects!$A$3:$B$21,2,FALSE),"") | M29: =IF(AND(K29<>"",L29<>""),K29-L29,"") | N29: =IF(AND(M29<>"",K29<>"",K29<>0),M29/K29,"")
E30: =IFERROR(VLOOKUP(D30,Projects!$A$3:$B$21,2,FALSE),"") | M30: =IF(AND(K30<>"",L30<>""),K30-L30,"") | N30: =IF(AND(M30<>"",K30<>"",K30<>0),M30/K30,"")
E31: =IFERROR(VLOOKUP(D31,Projects!$A$3:$B$21,2,FALSE),"") | M31: =IF(AND(K31<>"",L31<>""),K31-L31,"") | N31: =IF(AND(M31<>"",K31<>"",K31<>0),M31/K31,"")
E32: =IFERROR(VLOOKUP(D32,Projects!$A$3:$B$21,2,FALSE),"") | M32: =IF(AND(K32<>"",L32<>""),K32-L32,"") | N32: =IF(AND(M32<>"",K32<>"",K32<>0),M32/K32,"")
E33: =IFERROR(VLOOKUP(D33,Projects!$A$3:$B$21,2,FALSE),"") | M33: =IF(AND(K33<>"",L33<>""),K33-L33,"") | N33: =IF(AND(M33<>"",K33<>"",K33<>0),M33/K33,"")
E34: =IFERROR(VLOOKUP(D34,Projects!$A$3:$B$21,2,FALSE),"") | M34: =IF(AND(K34<>"",L34<>""),K34-L34,"") | N34: =IF(AND(M34<>"",K34<>"",K34<>0),M34/K34,"")
E35: =IFERROR(VLOOKUP(D35,Projects!$A$3:$B$21,2,FALSE),"") | M35: =IF(AND(K35<>"",L35<>""),K35-L35,"") | N35: =IF(AND(M35<>"",K35<>"",K35<>0),M35/K35,"")
E36: =IFERROR(VLOOKUP(D36,Projects!$A$3:$B$21,2,FALSE),"") | M36: =IF(AND(K36<>"",L36<>""),K36-L36,"") | N36: =IF(AND(M36<>"",K36<>"",K36<>0),M36/K36,"")
... E46: =IFERROR(VLOOKUP(D46,Projects!$A$3:$B$21,2,FALSE),"") | M46: =IF(AND(K46<>"",L46<>""),K46-L46,"") | N46: =IF(AND(M46<>"",K46<>"",K46<>0),M46/K46,"")
A49: ERP – Weekly Aggregated Summary
A50: Metric | B50: Value
A51: Total Tasks Logged | B51: =COUNTA(G7:G46) -> 5
A52: Total Time Without AI (hrs) | B52: =SUM(K7:K46) -> 156
...

Sheet BFSI
A1: EAS AI Adoption – Weekly Tracking Sheet – Financial Services Solutions (BFSI)
A2: EAS Overall AI SPOC: | D2: Omar Ibrahim
A3: BFSI Practice Head: | D3: Mohab ElHaddad
A4: BFSI AI SPOC: | D4: Omar Ibrahim
A6: Week # | B6: Week Start Date | C6: Week End Date | D6: Project Name | E6: Project Code | F6: Employee Name | G6: Task / Activity | H6: Task Category | I6: AI Tool Used | J6: Prompt / Approach | K6: Time Without AI (hrs) | L6: Time With AI (hrs) | M6: Time Saved (hrs) | N6: Efficiency Gain % | O6: Quality Rating (1-5) | P6: Status | Q6: Notes / Learnings
A7: 1 | B7: 15/2/2026 | C7: 19/2/2026 | D7: Go Money MICRO FINANCE LENDING PLATFORM | E7: =IFERROR(VLOOKUP(D7,Projects!$G$3:$H$21,2,FALSE),"") -> A1023401 | F7: Miral Soliman | G7: product catalog | H7: Documentation | I7: Github Copilot | K7: 2 | L7: 1.5 | M7: =IF(AND(K7<>"",L7<>""),K7-L7,"") -> 0.5 | N7: =IF(AND(M7<>"",K7<>"",K7<>0),M7/K7,"") -> 0.25 | P7: Completed
A8: 1 | B8: 15/2/2026 | C8: 19/2/2026 | D8: Go Money MICRO FINANCE LENDING PLATFORM | E8: =IFERROR(VLOOKUP(D8,Projects!$G$3:$H$21,2,FALSE),"") -> A1023401 | F8: Miral Soliman | G8: Project scope questionnaire | H8: Documentation | I8: Github Copilot | K8: 4 | L8: 3.05 | M8: =IF(AND(K8<>"",L8<>""),K8-L8,"") -> 0.95 | N8: =IF(AND(M8<>"",K8<>"",K8<>0),M8/K8,"") -> 0.2375 | P8: Completed
A9: 1 | B9: 15/2/2026 | C9: 19/2/2026 | D9: Go Money MICRO FINANCE LENDING PLATFORM | E9: =IFERROR(VLOOKUP(D9,Projects!$G$3:$H$21,2,FALSE),"") -> A1023401 | F9: Gahada Bakry | G9: HLD/FSD | H9: Documentation | I9: Github Copilot | K9: 6 | L9: 5 | M9: =IF(AND(K9<>"",L9<>""),K9-L9,"") -> 1 | N9: =IF(AND(M9<>"",K9<>"",K9<>0),M9/K9,"") -> 0.16666667 | P9: Completed
A10: 1 | B10: 15/2/2026 | C10: 19/2/2026 | D10: Go Money MICRO FINANCE LENDING PLATFORM | E10: =IFERROR(VLOOKUP(D10,Projects!$G$3:$H$21,2,FALSE),"") -> A1023401 | F10: AL-Moataz Bellah Khamis Ahmed | G10: Development | H10: Development | I10: Github Copilot | K10: 6 | L10: 1.4 | M10: =IF(AND(K10<>"",L10<>""),K10-L10,"") -> 4.6 | N10: =IF(AND(M10<>"",K10<>"",K10<>0),M10/K10,"") -> 0.76666667 | P10: Completed
A11: 1 | B11: 15/2/2026 | C11: 19/2/2026 | D11: Go Money MICRO FINANCE LENDING PLATFORM | E11: =IFERROR(VLOOKUP(D11,Projects!$G$3:$H$21,2,FALSE),"") -> A1023401 | F11: AL-Moataz Bellah Khamis Ahmed | G11: Database | H11: Database | I11: Github Copilot | K11: 2 | L11: 0.4 | M11: =IF(AND(K11<>"",L11<>""),K11-L11,"") -> 1.6 | N11: =IF(AND(M11<>"",K11<>"",K11<>0),M11/K11,"") -> 0.8 | P11: Completed
A12: 1 | B12: 15/2/2026 | C12: 19/2/2026 | D12: Go Money MICRO FINANCE LENDING PLATFORM | E12: =IFERROR(VLOOKUP(D12,Projects!$G$3:$H$21,2,FALSE),"") -> A1023401 | F12: AL-Moataz Bellah Khamis Ahmed | G12: Development | H12: Development | I12: Github Copilot | K12: 4 | L12: 3 | M12: =IF(AND(K12<>"",L12<>""),K12-L12,"") -> 1 | N12: =IF(AND(M12<>"",K12<>"",K12<>0),M12/K12,"") -> 0.25 | P12: Completed
A13: 1 | B13: 15/2/2026 | C13: 19/2/2026 | D13: Go Money MICRO FINANCE LENDING PLATFORM | E13: =IFERROR(VLOOKUP(D13,Projects!$G$3:$H$21,2,FALSE),"") -> A1023401 | F13: AL-Moataz Bellah Khamis Ahmed | G13: Database | H13: Database | I13: Github Copilot | K13: 2 | L13: 0.5 | M13: =IF(AND(K13<>"",L13<>""),K13-L13,"") -> 1.5 | N13: =IF(AND(M13<>"",K13<>"",K13<>0),M13/K13,"") -> 0.75 | P13: Completed
A14: 1 | B14: 15/2/2026 | C14: 19/2/2026 | D14: Project C-Personal Finance | E14: =IFERROR(VLOOKUP(D14,Projects!$G$3:$H$21,2,FALSE),"") -> 12135001 | F14: AbdelRahman Badr Kamel | G14: Code Review | H14: Code Review | I14: Github Copilot | K14: 2 | L14: 1.5 | M14: =IF(AND(K14<>"",L14<>""),K14-L14,"") -> 0.5 | N14: =IF(AND(M14<>"",K14<>"",K14<>0),M14/K14,"") -> 0.25 | P14: Completed
A15: 1 | B15: 15/2/2026 | C15: 19/2/2026 | D15: Project C-Personal Finance | E15: =IFERROR(VLOOKUP(D15,Projects!$G$3:$H$21,2,FALSE),"") -> 12135001 | F15: AbdelRahman Badr Kamel | G15: Documentation | H15: Documentation | I15: Github Copilot | K15: 8 | L15: 6.5 | M15: =IF(AND(K15<>"",L15<>""),K15-L15,"") -> 1.5 | N15: =IF(AND(M15<>"",K15<>"",K15<>0),M15/K15,"") -> 0.1875 | P15: Completed
A16: 1 | B16: 15/2/2026 | C16: 19/2/2026 | D16: Project C-Personal Finance | E16: =IFERROR(VLOOKUP(D16,Projects!$G$3:$H$21,2,FALSE),"") -> 12135001 | F16: AL-Moataz Bellah Khamis Ahmed | G16: Development | H16: Development | I16: Github Copilot | K16: 4 | L16: 3 | M16: =IF(AND(K16<>"",L16<>""),K16-L16,"") -> 1 | N16: =IF(AND(M16<>"",K16<>"",K16<>0),M16/K16,"") -> 0.25 | P16: Completed
A17: 1 | B17: 15/2/2026 | C17: 19/2/2026 | D17: Project C-Personal Finance | E17: =IFERROR(VLOOKUP(D17,Projects!$G$3:$H$21,2,FALSE),"") -> 12135001 | F17: AL-Moataz Bellah Khamis Ahmed | G17: Database | H17: Database | I17: Github Copilot | K17: 2 | L17: 0.5 | M17: =IF(AND(K17<>"",L17<>""),K17-L17,"") -> 1.5 | N17: =IF(AND(M17<>"",K17<>"",K17<>0),M17/K17,"") -> 0.75 | P17: Completed
A18: 2 | B18: 22/2/2026 | C18: 26/2/2026 | D18: Go Money MICRO FINANCE LENDING PLATFORM | E18: =IFERROR(VLOOKUP(D18,Projects!$G$3:$H$21,2,FALSE),"") -> A1023401 | F18: Miral Soliman | H18: Documentation | I18: Github Copilot | M18: =IF(AND(K18<>"",L18<>""),K18-L18,"") | N18: =IF(AND(M18<>"",K18<>"",K18<>0),M18/K18,"")
A19: 2 | B19: 22/2/2026 | C19: 26/2/2026 | D19: Go Money MICRO FINANCE LENDING PLATFORM | E19: =IFERROR(VLOOKUP(D19,Projects!$G$3:$H$21,2,FALSE),"") -> A1023401 | F19: Miral Soliman | H19: Documentation | I19: Github Copilot | M19: =IF(AND(K19<>"",L19<>""),K19-L19,"") | N19: =IF(AND(M19<>"",K19<>"",K19<>0),M19/K19,"")
A20: 2 | B20: 22/2/2026 | C20: 26/2/2026 | D20: Go Money MICRO FINANCE LENDING PLATFORM | E20: =IFERROR(VLOOKUP(D20,Projects!$G$3:$H$21,2,FALSE),"") -> A1023401 | F20: Gahada Bakry | H20: Documentation | I20: Github Copilot | M20: =IF(AND(K20<>"",L20<>""),K20-L20,"") | N20: =IF(AND(M20<>"",K20<>"",K20<>0),M20/K20,"")
A21: 2 | B21: 22/2/2026 | C21: 26/2/2026 | D21: Go Money MICRO FINANCE LENDING PLATFORM | E21: =IFERROR(VLOOKUP(D21,Projects!$G$3:$H$21,2,FALSE),"") -> A1023401 | F21: AL-Moataz Bellah Khamis Ahmed | G21: Development | H21: Development | I21: Github Copilot | K21: 3 | L21: 0.5 | M21: =IF(AND(K21<>"",L21<>""),K21-L21,"") -> 2.5 | N21: =IF(AND(M21<>"",K21<>"",K21<>0),M21/K21,"") -> 0.83333333 | P21: Completed
A22: 2 | B22: 22/2/2026 | C22: 26/2/2026 | D22: Go Money MICRO FINANCE LENDING PLATFORM | E22: =IFERROR(VLOOKUP(D22,Projects!$G$3:$H$21,2,FALSE),"") -> A1023401 | F22: AL-Moataz Bellah Khamis Ahmed | G22: Database | H22: Development | I22: Github Copilot | K22: 3 | L22: 2.5 | M22: =IF(AND(K22<>"",L22<>""),K22-L22,"") -> 0.5 | N22: =IF(AND(M22<>"",K22<>"",K22<>0),M22/K22,"") -> 0.16666667 | P22: Completed
A23: 2 | B23: 22/2/2026 | C23: 26/2/2026 | D23: Go Money MICRO FINANCE LENDING PLATFORM | E23: =IFERROR(VLOOKUP(D23,Projects!$G$3:$H$21,2,FALSE),"") -> A1023401 | F23: AL-Moataz Bellah Khamis Ahmed | G23: Development | H23: Database | I23: Github Copilot | K23: 3 | L23: 1 | M23: =IF(AND(K23<>"",L23<>""),K23-L23,"") -> 2 | N23: =IF(AND(M23<>"",K23<>"",K23<>0),M23/K23,"") -> 0.66666667 | P23: Completed
A24: 2 | B24: 22/2/2026 | C24: 26/2/2026 | D24: Project C-Personal Finance | E24: =IFERROR(VLOOKUP(D24,Projects!$G$3:$H$21,2,FALSE),"") -> 12135001 | F24: AbdelRahman Badr Kamel | G24: Code Review | H24: Code Review | I24: Github Copilot | K24: 3 | L24: 2 | M24: =IF(AND(K24<>"",L24<>""),K24-L24,"") -> 1 | N24: =IF(AND(M24<>"",K24<>"",K24<>0),M24/K24,"") -> 0.33333333 | P24: Completed
A25: 2 | B25: 22/2/2026 | C25: 26/2/2026 | D25: Project C-Personal Finance | E25: =IFERROR(VLOOKUP(D25,Projects!$G$3:$H$21,2,FALSE),"") -> 12135001 | F25: AbdelRahman Badr Kamel | G25: Documentation | H25: Documentation | I25: Github Copilot | K25: 2 | L25: 1.5 | M25: =IF(AND(K25<>"",L25<>""),K25-L25,"") -> 0.5 | N25: =IF(AND(M25<>"",K25<>"",K25<>0),M25/K25,"") -> 0.25 | P25: Completed
A26: 2 | B26: 22/2/2026 | C26: 26/2/2026 | D26: Project C-Personal Finance | E26: =IFERROR(VLOOKUP(D26,Projects!$G$3:$H$21,2,FALSE),"") -> 12135001 | F26: AL-Moataz Bellah Khamis Ahmed | G26: Development | H26: Development | I26: Github Copilot | K26: 3 | L26: 2.5 | M26: =IF(AND(K26<>"",L26<>""),K26-L26,"") -> 0.5 | N26: =IF(AND(M26<>"",K26<>"",K26<>0),M26/K26,"") -> 0.16666667 | P26: Completed
A27: 2 | B27: 22/2/2026 | C27: 26/2/2026 | D27: Project C-Personal Finance | E27: =IFERROR(VLOOKUP(D27,Projects!$G$3:$H$21,2,FALSE),"") -> 12135001 | F27: AL-Moataz Bellah Khamis Ahmed | G27: Database | H27: Database | I27: Github Copilot | K27: 3 | L27: 1 | M27: =IF(AND(K27<>"",L27<>""),K27-L27,"") -> 2 | N27: =IF(AND(M27<>"",K27<>"",K27<>0),M27/K27,"") -> 0.66666667 | P27: Completed
A28: 6 | B28: 24/3/2026 | C28: 26/3/2026 | D28: Go Money MICRO FINANCE LENDING PLATFORM | E28: =IFERROR(VLOOKUP(D28,Projects!$G$3:$H$21,2,FALSE),"") -> A1023401 | F28: Omar Ibrahim | G28: Code Review | H28: Code Review | I28: Claude | K28: 8 | L28: 2 | M28: =IF(AND(K28<>"",L28<>""),K28-L28,"") -> 6 | N28: =IF(AND(M28<>"",K28<>"",K28<>0),M28/K28,"") -> 0.75 | P28: Completed
A29: 6 | B29: 24/3/2026 | C29: 26/3/2026 | D29: Project C-Personal Finance | E29: =IFERROR(VLOOKUP(D29,Projects!$G$3:$H$21,2,FALSE),"") -> 12135001 | F29: AbdelRahman Badr Kamel | G29: Development | H29: Development | I29: Github Copilot | K29: 8 | L29: 6 | M29: =IF(AND(K29<>"",L29<>""),K29-L29,"") -> 2 | N29: =IF(AND(M29<>"",K29<>"",K29<>0),M29/K29,"") -> 0.25 | P29: Completed | Q29: We used Copilot for identifying the steps and perquisites for enabling HTTPS on WebLogic application server using .pfx certificates.
A30: 7 | B30: 29/3/2026 | C30: 46057 | D30: Project C-Personal Finance | E30: =IFERROR(VLOOKUP(D30,Projects!$G$3:$H$21,2,FALSE),"") -> 12135001 | F30: AbdelRahman Badr Kamel | G30: Documentation | H30: Documentation | I30: Claude | K30: 8 | L30: 7 | M30: =IF(AND(K30<>"",L30<>""),K30-L30,"") -> 1 | N30: =IF(AND(M30<>"",K30<>"",K30<>0),M30/K30,"") -> 0.125 | P30: Completed | Q30: Validating LLD sequence diagrams
A31: 7 | B31: 29/3/2026 | C31: 46057 | D31: Project C-Personal Finance | E31: =IFERROR(VLOOKUP(D31,Projects!$G$3:$H$21,2,FALSE),"") -> 12135001 | F31: AbdelRahman Badr Kamel | G31: Code Review | H31: Code Review | I31: Claude | K31: 8 | L31: 5 | M31: =IF(AND(K31<>"",L31<>""),K31-L31,"") -> 3 | N31: =IF(AND(M31<>"",K31<>"",K31<>0),M31/K31,"") -> 0.375 | P31: Completed
A32: 7 | B32: 29/3/2026 | C32: 46057 | D32: Go Money MICRO FINANCE LENDING PLATFORM | E32: =IFERROR(VLOOKUP(D32,Projects!$G$3:$H$21,2,FALSE),"") -> A1023401 | F32: AL-Moataz Bellah Khamis Ahmed | G32: Development | H32: Development | I32: Github Copilot | K32: 7 | L32: 1.5 | M32: =IF(AND(K32<>"",L32<>""),K32-L32,"") -> 5.5 | N32: =IF(AND(M32<>"",K32<>"",K32<>0),M32/K32,"") -> 0.78571429 | P32: Completed
A33: 7 | B33: 29/3/2026 | C33: 46057 | D33: Go Money MICRO FINANCE LENDING PLATFORM | E33: =IFERROR(VLOOKUP(D33,Projects!$G$3:$H$21,2,FALSE),"") -> A1023401 | F33: AL-Moataz Bellah Khamis Ahmed | G33: Development | H33: Development | I33: Claude | K33: 10 | L33: 2 | M33: =IF(AND(K33<>"",L33<>""),K33-L33,"") -> 8 | N33: =IF(AND(M33<>"",K33<>"",K33<>0),M33/K33,"") -> 0.8 | P33: Completed | Q33: Claude was significantly helpful regarding the infinity Visualizer UI tool
A34: 7 | B34: 29/3/2026 | C34: 46057 | D34: Go Money MICRO FINANCE LENDING PLATFORM | E34: =IFERROR(VLOOKUP(D34,Projects!$G$3:$H$21,2,FALSE),"") -> A1023401 | F34: AL-Moataz Bellah Khamis Ahmed | G34: Code Review / Enhancements | H34: Code Review / Enhancements | I34: Claude | K34: 4 | L34: 0.5 | M34: =IF(AND(K34<>"",L34<>""),K34-L34,"") -> 3.5 | N34: =IF(AND(M34<>"",K34<>"",K34<>0),M34/K34,"") -> 0.875 | P34: Completed
A35: 7 | B35: 29/3/2026 | C35: 46057 | D35: ServiceNow | E35: Demand | F35: Omar Ibrahim | G35: HLD | H35: Documentation | I35: Github Copilot | K35: 6 | L35: 2 | M35: =IF(AND(K35<>"",L35<>""),K35-L35,"") -> 4 | N35: =IF(AND(M35<>"",K35<>"",K35<>0),M35/K35,"") -> 0.66666667 | O35: 4 | P35: Completed
A36: 7 | B36: 29/3/2026 | C36: 46057 | D36: CDF | E36: Demand | F36: Omar Ibrahim | G36: RFP | H36: Documentation | I36: Github Copilot | K36: 7 | L36: 1 | M36: =IF(AND(K36<>"",L36<>""),K36-L36,"") -> 6 | N36: =IF(AND(M36<>"",K36<>"",K36<>0),M36/K36,"") -> 0.85714286 | O36: 4 | P36: Completed
A37: 8 | B37: 46146 | C37: 46269 | D37: UCDE | E37: - | F37: Omar Ibrahim | G37: Experian Reverse engineering and FSD | H37: Documentation | I37: Github Copilot | J37: Gave Copilot multiple old documentation to format in a readible business way and KT doecumentation | K37: 12 | L37: 2 | M37: =IF(AND(K37<>"",L37<>""),K37-L37,"") -> 10 | N37: =IF(AND(M37<>"",K37<>"",K37<>0),M37/K37,"") -> 0.83333333 | O37: 4 | P37: Completed
A38: 8 | B38: 46146 | C38: 46269 | D38: ARB Digital Core Banking - Personal Finance | E38: - | F38: Omar Ibrahim | G38: L3 tickets analysis (900+) | H38: Documentation | I38: Claude | J38: extracted Jira raw data for all L3 and provided claude clear prompts to tailor and generate a report for ARB CIO and top managments as a defence for dev team | K38: 20 | L38: 6 | M38: =IF(AND(K38<>"",L38<>""),K38-L38,"") -> 14 | N38: =IF(AND(M38<>"",K38<>"",K38<>0),M38/K38,"") -> 0.7 | O38: 4.8 | P38: Completed
E39: =IFERROR(VLOOKUP(D39,Projects!$G$3:$H$21,2,FALSE),"") | M39: =IF(AND(K39<>"",L39<>""),K39-L39,"") | N39: =IF(AND(M39<>"",K39<>"",K39<>0),M39/K39,"")
E40: =IFERROR(VLOOKUP(D40,Projects!$G$3:$H$21,2,FALSE),"") | M40: =IF(AND(K40<>"",L40<>""),K40-L40,"") | N40: =IF(AND(M40<>"",K40<>"",K40<>0),M40/K40,"")
E41: =IFERROR(VLOOKUP(D41,Projects!$G$3:$H$21,2,FALSE),"") | M41: =IF(AND(K41<>"",L41<>""),K41-L41,"") | N41: =IF(AND(M41<>"",K41<>"",K41<>0),M41/K41,"")
...

Sheet EPS
A1: EAS AI Adoption – Weekly Tracking Sheet – Payments Solutions EPS
A2: EAS Overall AI SPOC: | D2: Omar Ibrahim
A3: EPS Practice Head: | D3: Mohamed Ziaudin
A4: EPS AI SPOC: | D4: Yousef Milhem
A6: Week # | B6: Week Start Date | C6: Week End Date | D6: Project Name | E6: Project Code | F6: Employee Name | G6: Task / Activity | H6: Task Category | I6: AI Tool Used | J6: Prompt / Approach | K6: Time Without AI (hrs) | L6: Time With AI (hrs) | M6: Time Saved (hrs) | N6: Efficiency Gain % | O6: Quality Rating (1-5) | P6: Status | Q6: Notes / Learnings
A7: 1 | B7: 46124 | C7: 16-04-2026 | D7: ANB EPS Corporate Module | E7: =IFERROR(VLOOKUP(D7,Projects!$J$3:$K$21,2,FALSE),"") -> 12150101 | F7: Amol Kodre | G7: Providing Teams transcript to COPILOT prompt to generate MOM | H7: Documentation | I7: Github Copilot | J7: Need to conduct a meeting with transcript and send it from teams to coplito to generate MOM | K7: 1 | M7: =IF(AND(K7<>"",L7<>""),K7-L7,"") | N7: =IF(AND(M7<>"",K7<>"",K7<>0),M7/K7,"")
A8: 2 | B8: 19-04-2026 | C8: 23-04-2026 | D8: ANB EPS Corporate Module | E8: =IFERROR(VLOOKUP(D8,Projects!$J$3:$K$21,2,FALSE),"") -> 12150101 | F8: Amol Kodre | G8: Provide Code / Script provided by the bank of their current system, provide it to the copilot prompt and get it in our solution language | H8: Code Review | I8: Github Copilot | J8: Having like JAVA script from the customer and try to analyze it | K8: 1 | M8: =IF(AND(K8<>"",L8<>""),K8-L8,"") | N8: =IF(AND(M8<>"",K8<>"",K8<>0),M8/K8,"")
A9: 3 | B9: 46146 | C9: 46269 | D9: ANB EPS Corporate Module | E9: =IFERROR(VLOOKUP(D9,Projects!$J$3:$K$21,2,FALSE),"") -> 12150101 | F9: Amol Kodre | G9: Ask Copilot prompt to generate SWIFT MT / MX samples for different message types | H9: Testing | I9: Github Copilot | J9: Asked the prompt to provide some samples of different types / different currencies / ...etc. | K9: 0.5 | L9: 0.01 | M9: =IF(AND(K9<>"",L9<>""),K9-L9,"") -> 0.49 | N9: =IF(AND(M9<>"",K9<>"",K9<>0),M9/K9,"") -> 0.98 | O9: 4 | P9: Completed | Q9: Whatever provided seems to be fine, any tuning is being provided is taken into consieration
A10: 4 | B10: 46124 | C10: 16-04-2026 | D10: Migration of TiPlus backend interfaces to MQ based MT & MX | E10: =IFERROR(VLOOKUP(D10,Projects!$J$3:$K$21,2,FALSE),"") -> 12158001 | F10: Karthik Selvam | G10: Test Data Generation and Preparation | H10: Testing | I10: Github Copilot | M10: =IF(AND(K10<>"",L10<>""),K10-L10,"") | N10: =IF(AND(M10<>"",K10<>"",K10<>0),M10/K10,"")
A11: 5 | B11: 19-04-2026 | C11: 23-04-2026 | D11: ANB EPS Corporate Module | E11: =IFERROR(VLOOKUP(D11,Projects!$J$3:$K$21,2,FALSE),"") -> 12150101 | F11: Karthik Selvam | G11: User Story Enhancement for Tester Readability | H11: Testing | I11: Github Copilot | M11: =IF(AND(K11<>"",L11<>""),K11-L11,"") | N11: =IF(AND(M11<>"",K11<>"",K11<>0),M11/K11,"")
A12: 6 | B12: 26-04-2026 | C12: 30-04-2026 | D12: Migration of TiPlus backend interfaces to MQ based MT & MX | E12: =IFERROR(VLOOKUP(D12,Projects!$J$3:$K$21,2,FALSE),"") -> 12158001 | F12: Seikh Tanbir | G12: AI generates structured user guide content from scripts, process steps, and system descriptions, producing professional documentation drafts for review and refinement. | H12: Documentation | I12: Github Copilot | M12: =IF(AND(K12<>"",L12<>""),K12-L12,"") | N12: =IF(AND(M12<>"",K12<>"",K12<>0),M12/K12,"")
E13: =IFERROR(VLOOKUP(D13,Projects!$J$3:$K$21,2,FALSE),"") | M13: =IF(AND(K13<>"",L13<>""),K13-L13,"") | N13: =IF(AND(M13<>"",K13<>"",K13<>0),M13/K13,"")
E14: =IFERROR(VLOOKUP(D14,Projects!$J$3:$K$21,2,FALSE),"") | M14: =IF(AND(K14<>"",L14<>""),K14-L14,"") | N14: =IF(AND(M14<>"",K14<>"",K14<>0),M14/K14,"")
E15: =IFERROR(VLOOKUP(D15,Projects!$J$3:$K$21,2,FALSE),"") | M15: =IF(AND(K15<>"",L15<>""),K15-L15,"") | N15: =IF(AND(M15<>"",K15<>"",K15<>0),M15/K15,"")
E16: =IFERROR(VLOOKUP(D16,Projects!$J$3:$K$21,2,FALSE),"") | M16: =IF(AND(K16<>"",L16<>""),K16-L16,"") | N16: =IF(AND(M16<>"",K16<>"",K16<>0),M16/K16,"")
E17: =IFERROR(VLOOKUP(D17,Projects!$J$3:$K$21,2,FALSE),"") | M17: =IF(AND(K17<>"",L17<>""),K17-L17,"") | N17: =IF(AND(M17<>"",K17<>"",K17<>0),M17/K17,"")
E18: =IFERROR(VLOOKUP(D18,Projects!$J$3:$K$21,2,FALSE),"") | M18: =IF(AND(K18<>"",L18<>""),K18-L18,"") | N18: =IF(AND(M18<>"",K18<>"",K18<>0),M18/K18,"")
E19: =IFERROR(VLOOKUP(D19,Projects!$J$3:$K$21,2,FALSE),"") | M19: =IF(AND(K19<>"",L19<>""),K19-L19,"") | N19: =IF(AND(M19<>"",K19<>"",K19<>0),M19/K19,"")
E20: =IFERROR(VLOOKUP(D20,Projects!$J$3:$K$21,2,FALSE),"") | M20: =IF(AND(K20<>"",L20<>""),K20-L20,"") | N20: =IF(AND(M20<>"",K20<>"",K20<>0),M20/K20,"")
E21: =IFERROR(VLOOKUP(D21,Projects!$J$3:$K$21,2,FALSE),"") | M21: =IF(AND(K21<>"",L21<>""),K21-L21,"") | N21: =IF(AND(M21<>"",K21<>"",K21<>0),M21/K21,"")
E22: =IFERROR(VLOOKUP(D22,Projects!$J$3:$K$21,2,FALSE),"") | M22: =IF(AND(K22<>"",L22<>""),K22-L22,"") | N22: =IF(AND(M22<>"",K22<>"",K22<>0),M22/K22,"")
E23: =IFERROR(VLOOKUP(D23,Projects!$J$3:$K$21,2,FALSE),"") | M23: =IF(AND(K23<>"",L23<>""),K23-L23,"") | N23: =IF(AND(M23<>"",K23<>"",K23<>0),M23/K23,"")
E24: =IFERROR(VLOOKUP(D24,Projects!$J$3:$K$21,2,FALSE),"") | M24: =IF(AND(K24<>"",L24<>""),K24-L24,"") | N24: =IF(AND(M24<>"",K24<>"",K24<>0),M24/K24,"")
... E46: =IFERROR(VLOOKUP(D46,Projects!$J$3:$K$21,2,FALSE),"") | M46: =IF(AND(K46<>"",L46<>""),K46-L46,"") | N46: =IF(AND(M46<>"",K46<>"",K46<>0),M46/K46,"")
A49: EPS – Weekly Aggregated Summary
A50: Metric | B50: Value
A51: Total Tasks Logged | B51: =COUNTA(G7:G46) -> 6
A52: Total Time Without AI (hrs) | B52: =SUM(K7:K46) -> 2.5
A53: Total Time With AI (hrs) | B53: =SUM(L7:L46) -> 0.01
A54: Total Time Saved (hrs) | B54: =SUM(M7:M46) -> 0.49
A55: Average Efficiency Gain % | B55: =IFERROR(AVERAGE(N7:N46),"") -> 0.98
A56: Average Quality Rating | B56: =IFERROR(AVERAGE(O7:O46),"") -> 4
A57: Tasks Completed | B57: =COUNTIF(P7:P46,"Completed") -> 1
A58: Tasks In Progress | B58: =COUNTIF(P7:P46,"In Progress") -> 0

Sheet EPCS
A1: EAS AI Adoption – Weekly Tracking Sheet – Enterprise Portfolio & Content Solutions
A2: EAS Overall AI SPOC: | D2: Omar Ibrahim
A3: EPCS Practice Head: | D3: Mohamed Mobarak
A4: EPCS AI SPOC: | D4: Mohamed Mobarak
A6: Week # | B6: Week Start Date | C6: Week End Date | D6: Project Name | E6: Project Code | F6: Employee Name | G6: Task / Activity | H6: Task Category | I6: AI Tool Used | J6: Prompt / Approach | K6: Time Without AI (hrs) | L6: Time With AI (hrs) | M6: Time Saved (hrs) | N6: Efficiency Gain % | O6: Quality Rating (1-5) | P6: Status | Q6: Notes / Learnings
D7: ART - Alfresco DMS Production Support Services | E7: =IFERROR(VLOOKUP(D7,Projects!$P$3:$Q$21,2,FALSE),"") -> 14005204 | G7: configure certifcation for elastic search | H7: Development | I7: Github Copilot | M7: =IF(AND(K7<>"",L7<>""),K7-L7,"") | N7: =IF(AND(M7<>"",K7<>"",K7<>0),M7/K7,"") | O7: 4 | Q7: by Omar GamalEldeen
D8: DMS Activities | E8: =IFERROR(VLOOKUP(D8,Projects!$P$3:$Q$21,2,FALSE),"") -> 51014108-001 | G8: add localization in Alfresco digital workspace | H8: Development | I8: Github Copilot | M8: =IF(AND(K8<>"",L8<>""),K8-L8,"") | N8: =IF(AND(M8<>"",K8<>"",K8<>0),M8/K8,"") | O8: 5 | Q8: by Omar GamalEldeen
D9: DMS Activities | E9: =IFERROR(VLOOKUP(D9,Projects!$P$3:$Q$21,2,FALSE),"") -> 51014108-001 | G9: Update scripts to run in different environments | H9: Development | I9: Github Copilot | M9: =IF(AND(K9<>"",L9<>""),K9-L9,"") | N9: =IF(AND(M9<>"",K9<>"",K9<>0),M9/K9,"") | O9: 5 | Q9: by Omar GamalEldeen
E10: =IFERROR(VLOOKUP(D10,Projects!$P$3:$Q$21,2,FALSE),"") | M10: =IF(AND(K10<>"",L10<>""),K10-L10,"") | N10: =IF(AND(M10<>"",K10<>"",K10<>0),M10/K10,"")
E11: =IFERROR(VLOOKUP(D11,Projects!$P$3:$Q$21,2,FALSE),"") | M11: =IF(AND(K11<>"",L11<>""),K11-L11,"") | N11: =IF(AND(M11<>"",K11<>"",K11<>0),M11/K11,"")
E12: =IFERROR(VLOOKUP(D12,Projects!$P$3:$Q$21,2,FALSE),"") | M12: =IF(AND(K12<>"",L12<>""),K12-L12,"") | N12: =IF(AND(M12<>"",K12<>"",K12<>0),M12/K12,"")
E13: =IFERROR(VLOOKUP(D13,Projects!$P$3:$Q$21,2,FALSE),"") | M13: =IF(AND(K13<>"",L13<>""),K13-L13,"") | N13: =IF(AND(M13<>"",K13<>"",K13<>0),M13/K13,"")
E14: =IFERROR(VLOOKUP(D14,Projects!$P$3:$Q$21,2,FALSE),"") | M14: =IF(AND(K14<>"",L14<>""),K14-L14,"") | N14: =IF(AND(M14<>"",K14<>"",K14<>0),M14/K14,"")
E15: =IFERROR(VLOOKUP(D15,Projects!$P$3:$Q$21,2,FALSE),"") | M15: =IF(AND(K15<>"",L15<>""),K15-L15,"") | N15: =IF(AND(M15<>"",K15<>"",K15<>0),M15/K15,"")
E16: =IFERROR(VLOOKUP(D16,Projects!$P$3:$Q$21,2,FALSE),"") | M16: =IF(AND(K16<>"",L16<>""),K16-L16,"") | N16: =IF(AND(M16<>"",K16<>"",K16<>0),M16/K16,"")
E17: =IFERROR(VLOOKUP(D17,Projects!$P$3:$Q$21,2,FALSE),"") | M17: =IF(AND(K17<>"",L17<>""),K17-L17,"") | N17: =IF(AND(M17<>"",K17<>"",K17<>0),M17/K17,"")
E18: =IFERROR(VLOOKUP(D18,Projects!$P$3:$Q$21,2,FALSE),"") | M18: =IF(AND(K18<>"",L18<>""),K18-L18,"") | N18: =IF(AND(M18<>"",K18<>"",K18<>0),M18/K18,"")
E19: =IFERROR(VLOOKUP(D19,Projects!$P$3:$Q$21,2,FALSE),"") | M19: =IF(AND(K19<>"",L19<>""),K19-L19,"") | N19: =IF(AND(M19<>"",K19<>"",K19<>0),M19/K19,"")
E20: =IFERROR(VLOOKUP(D20,Projects!$P$3:$Q$21,2,FALSE),"") | M20: =IF(AND(K20<>"",L20<>""),K20-L20,"") | N20: =IF(AND(M20<>"",K20<>"",K20<>0),M20/K20,"")
E21: =IFERROR(VLOOKUP(D21,Projects!$P$3:$Q$21,2,FALSE),"") | M21: =IF(AND(K21<>"",L21<>""),K21-L21,"") | N21: =IF(AND(M21<>"",K21<>"",K21<>0),M21/K21,"")
... E46: =IFERROR(VLOOKUP(D46,Projects!$P$3:$Q$21,2,FALSE),"") | M46: =IF(AND(K46<>"",L46<>""),K46-L46,"") | N46: =IF(AND(M46<>"",K46<>"",K46<>0),M46/K46,"")
A49: EPCS – Weekly Aggregated Summary
A50: Metric | B50: Value
A51: Total Tasks Logged | B51: =COUNTA(G7:G46) -> 3
A52: Total Time Without AI (hrs) | B52: =SUM(K7:K46) -> 0
A53: Total Time With AI (hrs) | B53: =SUM(L7:L46) -> 0
A54: Total Time Saved (hrs) | B54: =SUM(M7:M46) -> 0
A55: Average Efficiency Gain % | B55: =IFERROR(AVERAGE(N7:N46),"")
A56: Average Quality Rating | B56: =IFERROR(AVERAGE(O7:O46),"") -> 4.6666667
A57: Tasks Completed | B57: =COUNTIF(P7:P46,"Completed") -> 0
A58: Tasks In Progress | B58: =COUNTIF(P7:P46,"In Progress") -> 0

Sheet AI_Projects
A1: Practice | B1: Project Code | C1: Contract Number | D1: Customer Name | E1: Contract Value | F1: Contract Start Date | G1: Contract End Date | H1: Project Name | I1: Revenue Type | J1: Line Type | K1: Project Manager
A2: BFSI | B2: 12135001 | C2: KSA-25-0123 | D2: Al Rajhi Bank | E2: 7420000 | F2: 45680 | G2: 45930 | H2: Project C-Personal Finance | I2: Fixed Price | J2: Internal | K2: E1919 - Youssef Mohamed Yousef Salah (ymyoussef)
A3: BFSI | B3: A1023401 | C3: KSA-25-0319 | D3: Etihad GO Telecom Company | E3: 2250000 | F3: 45785 | G3: 46068 | H3: Go Money MICRO FINANCE LENDING PLATFORM | I3: Fixed Price | J3: Internal | K3: Q1981 - Sarah Ali Mohamed El Mansoury (selmansoury)
A4: ERP | B4: 56000301 | C4: KSA-25-0797 | D4: Remat Al-Riyadh | E4: 14941796 | F4: 46006 | G4: 46568 | H4: RRM ERP Cloud Services Implementation | I4: Fixed Price | J4: Internal | K4: A0038: Mohamed Abdul Aziz Khaleel
A5: ERP | B5: C1007201 | D5: ITSM | H5: ITSM Project | I5: Fixed Price | J5: Internal
A6: GRC | B6: 12164301 | F6: 45992 | G6: 46356 | H6: VAT Application Support | I6: TM | J6: External | K6: Maisam Ali
A7: GRC | B7: 12144401 | F7: 45809 | G7: 46174 | H7: ANB Change Request VAT Reconcilation | I7: Fixed Price | J7: External | K7: Maisam Ali
A8: GRC | B8: 12154701 | F8: 45550 | G8: 46295 | H8: ANB Consumer Loans Historical Reconcilation | I8: Fixed Price | J8: External | K8: Maisam Ali
A9: CES | B9: 62002301 | C9: KSA-23-0238 | D9: Ministry of Health | E9: 9750013 | F9: 45017 | G9: 31-12-2026 | H9: MOH - Portals Support & Management | I9: Fixed Price | J9: Internal | K9: S0013 - Simon Jiries Istefan Salameh (ssalameh)
A10: CES | B10: N/A | C10: KSA-25-0854 | D10: Zakat, Tax and Customs Authority | E10: 2608600 | F10: 45759 | G10: 30-09-2027 | H10: تطوير الملف التعريفي الموحد للعملاء | I10: Fixed Price | J10: Internal | K10: E0546 - Mohammed Mustafa Mohammed El Marasy (melmarasy)
A11: CES | B11: 23045701 | C11: KSA-25-0718 | D11: Tawtheeq Company for Registering Financial Lease Contracts | E11: 600000 | F11: 30-11-2025 | G11: 46031 | H11: tawtheeq service now crm | I11: Fixed Price | J11: Internal | K11: E2048 - Salah Shahat Hassanin Elayat (selayat)
A12: BFSI | B12: 13011901 | C12: KSA-25-0532 | D12: Emkan Finance Company | E12: 1890000 | F12: 45666 | G12: 31-12-2025 | H12: Emkan E-Commerce | I12: Fixed Price | J12: Internal | K12: E3046 - Mohammad Abdul Muttalib Khan (akhan)
A13: BFSI | B13: 13012401 | C13: KSA-25-0500 | D13: Emkan Finance Company | E13: 2070000 | F13: 20-10-2025 | G13: 31-05-2026 | H13: Emkan Freelance | I13: Fixed Price | J13: Internal | K13: E3046 - Mohammad Abdul Muttalib Khan (akhan)
A14: BFSI | B14: 13012501 | C14: KSA-25-0597 | D14: Emkan Finance Company | E14: 2310000 | F14: 45667 | G14: 31-05-2026 | H14: Emkan Revamp | I14: Fixed Price | J14: Internal | K14: E2994 - Ahmed Ali Abdelaziz Ismail Khater (ahmed.khater)
A15: BFSI | B15: 13005301 | C15: KSA-24-0094 | D15: Emkan Finance Company | E15: 44776400 | F15: 18-03-2024 | G15: 31-12-2025 | H15: Emkan - BNPL Implementation (LMS + LOS) | I15: Fixed Price | J15: Internal | K15: E3046 - Mohammad Abdul Muttalib Khan (akhan)
A16: BFSI | B16: 13008001 | C16: KSA-24-0317 | D16: Emkan Finance Company | E16: 8100000 | F16: 18-08-2024 | G16: 31-12-2025 | H16: Emkan - Apple Project Implementation | I16: Fixed Price | J16: Internal | K16: E2584 - Waleed Mohamed Amin Elsaid Abdelhamid Saleh (wsaleh)
A17: BFSI | B17: 13008101 | C17: KSA-24-0447 | D17: Emkan Finance Company | E17: 11895902 | F17: 45514 | G17: 45667 | H17: Emkan - SME Product Suite Implementation (B2B) | I17: Fixed Price | J17: Internal | K17: E1915 - Mohab Mahmoud Kamel Elhadad (melhadad)
A18: BFSI | B18: 13013201 | C18: KSA-25-0675 | D18: Emkan Finance Company | E18: 1601419 | F18: 45911 | G18: 46236 | H18: EMKAN Vulnerability Report | I18: Fixed Price | J18: Internal | K18: E1534 - Fathy Ahmed Shehata Khattab (fkhatab)
A19: BFSI | B19: A1023401 | C19: KSA-25-0319 | D19: Etihad GO Telecom Company | E19: 2250000 | F19: 45874 | G19: 15-02-2026 | H19: Go Money MICRO FINANCE LENDING PLATFORM | I19: Fixed Price | J19: Internal | K19: Q1981 - Sarah Ali Mohamed El Mansoury (selmansoury)
A20: BFSI | B20: 94000802 | C20: KSA-24-0304 | D20: Tourism Development Fund | E20: 5130400 | F20: 45604 | G20: 46334 | H20: TDF Transact Support and Enhancement - Temenos T24 | I20: Fixed Price | J20: Internal | K20: Q1981 - Sarah Ali Mohamed El Mansoury (selmansoury)
A21: BFSI | B21: 94000601 | C21: KSA-23-0116 | D21: Tourism Development Fund | E21: 3478000 | F21: 26-09-2023 | G21: 19-06-2025 | H21: TDF - Risk Monitoring and Reporting Portal | I21: Fixed Price | J21: Internal | K21: Q1981 - Sarah Ali Mohamed El Mansoury (selmansoury)
A22: Payments Solutions | B22: 12158001 | D22: ANB | E22: 490000 | F22: 45922 | G22: 46203 | H22: Migration of TiPlus backend interfaces to MQ based MT & MX | I22: Fixed Price | J22: Internal | K22: E2195 - HASEEB ULLAH KHAN
A23: Payments Solutions | B23: 12150101 | D23: ANB | E23: 2688760 | F23: 45807 | G23: 46357 | H23: ANB EPS Corporate Module | I23: Fixed Price | J23: Internal | K23: E2195 - HASEEB ULLAH KHAN

Sheet GRC
A1: EAS AI Adoption – Weekly Tracking Sheet – GRC
A2: EAS Overall AI SPOC: | D2: Omar Ibrahim
A3: GRC Practice Head: | D3: Ahmed Madkour
A4: GRC AI SPOC: | D4: Mohamed Essam
A6: Week # | B6: Week Start Date | C6: Week End Date | D6: Project Name | E6: Project Code | F6: Employee Name | G6: Task / Activity | H6: Task Category | I6: AI Tool Used | J6: Prompt / Approach | K6: Time Without AI (hrs) | L6: Time With AI (hrs) | M6: Time Saved (hrs) | N6: Efficiency Gain % | O6: Quality Rating (1-5) | P6: Status | Q6: Notes / Learnings
A7: 1 | B7: 15/03/26 | C7: 19/03/26 | D7: VAT Application Support | E7: 12164301 | F7: Yousef Elshabrawy | G7: Resolving ORA-01555 Snapshot Too Old Error | H7: Database | I7: Github Copilot | J7: What is ORA-01555: snapshot too old? | K7: 4 | L7: 0.5 | M7: =IF(AND(K7<>"",L7<>""),K7-L7,"") -> 3.5 | N7: =IF(AND(M7<>"",K7<>"",K7<>0),M7/K7,"") -> 0.875 | O7: 5 | P7: Completed | Q7: This ORA-01555 error means your long-running query needed older UNDO data, but Oracle had already overwritten it.
A8: 2 | B8: 22/03/26 | C8: 26/03/26 | D8: VAT Application Support | E8: 12164301 | F8: Yousef Elshabrawy | G8: SQL Query Optimization | H8: Database | I8: Github Copilot | J8: Giving the query and asking about the performance tunning techniques I can use. | K8: 8 | L8: 2 | M8: =IF(AND(K8<>"",L8<>""),K8-L8,"") -> 6 | N8: =IF(AND(M8<>"",K8<>"",K8<>0),M8/K8,"") -> 0.75 | O8: 4 | P8: Completed
A9: 1 | B9: 15/03/26 | C9: 19/03/26 | D9: ANB Change Request VAT Reconcilation | E9: 12144401 | F9: Umair Saleh | G9: Converting Static MERGE PL/SQL to Dynamic MERGE PL/SQL | H9: Development | I9: Github Copilot | J9: Optimization techniques for the procedures | K9: 2 | L9: 0.25 | M9: =IF(AND(K9<>"",L9<>""),K9-L9,"") -> 1.75 | N9: =IF(AND(M9<>"",K9<>"",K9<>0),M9/K9,"") -> 0.875 | O9: 5 | P9: Completed
A10: 2 | B10: 22/03/26 | C10: 26/03/26 | D10: ANB Change Request VAT Reconcilation | E10: 12144401 | F10: Umair Saleh | G10: SQL CASE to OR Condition Conversion | H10: Development | I10: Github Copilot | J10: Ask copilot to convert the query. | K10: 2 | L10: 0.25 | M10: =IF(AND(K10<>"",L10<>""),K10-L10,"") -> 1.75 | N10: =IF(AND(M10<>"",K10<>"",K10<>0),M10/K10,"") -> 0.875 | O10: 5 | P10: Completed
A11: 3 | B11: 46146 | C11: 46269 | D11: VAT Application Support | E11: 12164301 | F11: Yousef Elshabrawy | G11: Drop multiple partitions dynamically from a daliy partitioned table | H11: Database | I11: Github Copilot | J11: How to drop multiple partitions from a daily paritioned table in Oracle? | K11: 2 | L11: 0.25 | M11: =IF(AND(K11<>"",L11<>""),K11-L11,"") -> 1.75 | N11: =IF(AND(M11<>"",K11<>"",K11<>0),M11/K11,"") -> 0.875 | O11: 5 | P11: Completed
A12: 8 | B12: 46146 | C12: 46269 | D12: UCDE | E12: - | F12: Ahmed Younis | G12: Experian Reverse engineering and FSD | H12: Documentation | I12: Github Copilot | J12: Gave Copilot multiple old documentation to format in a readible business way and KT doecumentation | K12: 12 | L12: 2 | M12: =IF(AND(K12<>"",L12<>""),K12-L12,"") -> 10 | N12: =IF(AND(M12<>"",K12<>"",K12<>0),M12/K12,"") -> 0.83333333 | O12: 4 | P12: Completed
E13: =IFERROR(VLOOKUP(D13,Projects!$M$3:$N$21,2,FALSE),"") | M13: =IF(AND(K13<>"",L13<>""),K13-L13,"") | N13: =IF(AND(M13<>"",K13<>"",K13<>0),M13/K13,"")
E14: =IFERROR(VLOOKUP(D14,Projects!$M$3:$N$21,2,FALSE),"") | M14: =IF(AND(K14<>"",L14<>""),K14-L14,"") | N14: =IF(AND(M14<>"",K14<>"",K14<>0),M14/K14,"")
E15: =IFERROR(VLOOKUP(D15,Projects!$M$3:$N$21,2,FALSE),"") | M15: =IF(AND(K15<>"",L15<>""),K15-L15,"") | N15: =IF(AND(M15<>"",K15<>"",K15<>0),M15/K15,"")
E16: =IFERROR(VLOOKUP(D16,Projects!$M$3:$N$21,2,FALSE),"") | M16: =IF(AND(K16<>"",L16<>""),K16-L16,"") | N16: =IF(AND(M16<>"",K16<>"",K16<>0),M16/K16,"")
